Workbook

Sheet Dashboard
A1: MAISON 41 — COCKPIT QUOTIDIEN
A2: Conserverie artisanale · Bocaux Weck · 0 Additif · 0 Nitrite · Depuis 2023
A4: VISION DU JOUR
A5: Production du jour | E5: Marches / evenements du jour
A6: Lots prevus, autoclaves, temps estime (feuille Planning) | E6: Marches, livraisons, evenements (feuille Marches)
A8: INDICATEURS CLES
A9: CA mois en cours | B9: =IFERROR(SUMPRODUCT((MONTH(Ventes!A5:A504)=MONTH(TODAY()))*(YEAR(Ventes!A5:A504)=YEAR(TODAY()))*Ventes!G5:G504),0) -> #ERROR! | C9: EUR | E9: Lots planifies 7j | F9: =IFERROR(COUNTIFS(Planning!A4:A303,">="&TODAY(),Planning!A4:A303,"<="&TODAY()+7),0) -> #ERROR! | G9: lots
A10: Bocaux en stock | B10: =IFERROR(SUMIF(Stock!D208:D262,"<>",Stock!D208:D262),0) -> #ERROR! | C10: boc. | E10: Recettes actives | F10: =IFERROR(COUNTIF(Recettes!H4:H32,"Actif"),0) -> #ERROR! | G10: rec.
A11: MP en rupture | B11: =IFERROR(COUNTIF(Stock!G6:G205,"Rupture"),0) -> #ERROR! | C11: MP | E11: Charges fixes mensuelles | F11: =IFERROR(SUMIF(Charges!B4:B16,"Fixe",Charges!C4:C16),0) -> #ERROR! | G11: EUR
A13: ACTIONS RAPIDES
A14: Assistant Production | B14: Priorites de production, lots a lancer
A15: Achats a lancer | B15: MP a commander, quantites, fournisseurs
A16: Marches a preparer | B16: Stock recommande, prevision CA
A17: HACCP du jour | B17: Enregistrements, controles, non-conformites
A18: DDM a surveiller | B18: Lots proches DDM, actions
A19: Pilotage financier | B19: Seuil de rentabilite, marge, tresorerie
A21: NAVIGATION
A22: Referentiels | B22: MP Referentiel · Recettes · Detail Recettes · Prix Vente
A23: Operations | B23: Planning · Stock · Fiche Lot · Ventes · Marches
A24: Gestion | B24: Charges · Previsionnel · Compta
A25: Qualite | B25: HACCP · Plan Nettoyage · DDM · Autoclaves
A26: Pilotage | B26: Assistant Production · Assistant Decisions · CRM

Sheet AuditLog
A1: Horodatage | B1: Utilisateur | C1: Rôle | D1: Action | E1: Détail
A2: 46114.591 | B2: Alex | C2: ? | D2: saveLotProduction | E2: {"numLot":"LOT-20260402-003","recette":"Rillettes du Chef"}

Sheet MP Référentiel
A4: Code MP | B4: Designation | C4: Categorie | D4: Unite | E4: Fournisseur | F4: Prix EUR/U | G4: Date MAJ | H4: Stock min | I4: Allergenes | J4: Notes

Sheet Traçabilité Lots
A1: N° Lot | B1: Date Production | C1: Recette | D1: Opérateur | E1: Code MP | F1: Désignation MP | G1: Qté consommée (kg) | H1: N° Lot Fournisseur | I1: Fournisseur | J1: DLC Fournisseur | K1: Date Réception | L1: URL Photo Étiquette | M1: URL Dossier Drive

Sheet Avoirs
A4: Date | B4: N° Avoir | C4: Type | D4: Client | E4: Recette | F4: Gamme | G4: Format | H4: Qte | I4: PU HT | J4: Remise % | K4: Net HT | L4: TVA EUR | M4: TTC EUR | N4: Motif

Sheet Clients
A2: ID | B2: Prénom | C2: Nom | D2: Email | E2: Téléphone | F2: Adresse | G2: Département | H2: Canal | I2: Statut Ulule | J2: Vote recette | K2: Nb achats | L2: CA total | M2: Type | N2: Notes

Sheet Parc Machine
A1: ID | B1: Nom | C1: Type | D1: Cap_RR290 | E1: Cap_RR580 | F1: Cap_RR850 | G1: Cap_W050 | H1: Cap_W080 | I1: Debit_kg_h | J1: Conso_kW | K1: Statut | L1: Notes

Sheet Utilisateurs
A1: PIN | B1: Nom | C1: Role | D1: Planning | E1: Calculateur | F1: Logistique | G1: Machines | H1: Vente | I1: Reporting | J1: Doc | K1: Admin
A2: 2929 | B2: Alex | C2: Gérant | D2: TRUE | E2: TRUE | F2: TRUE | G2: TRUE | H2: TRUE | I2: TRUE | J2: TRUE | K2: TRUE
A3: 1111 | B3: Jean | C3: Ouvrier | D3: TRUE | E3: TRUE | F3: FALSE | G3: TRUE | H3: FALSE | I3: FALSE | J3: TRUE | K3: FALSE
A4: 2222 | B4: Julie | C4: Vendeuse | D4: FALSE | E4: FALSE | F4: FALSE | G4: FALSE | H4: TRUE | I4: FALSE | J4: TRUE | K4: FALSE
A5: 0 | B5: Expert | C5: Compta | D5: FALSE | E5: FALSE | F5: FALSE | G5: FALSE | H5: FALSE | I5: TRUE | J5: FALSE | K5: FALSE

Sheet 👤 Clients
A1: ID Client | B1: Prénom | C1: Nom | D1: Email | E1: Téléphone | F1: Adresse | G1: Département | H1: Canal origine | I1: Niveau Ulule | J1: Vote recette | K1: Nb commandes | L1: CA total TTC | M1: Dernière commande | N1: Date création | O1: Source | P1: Notes | Q1: Sync

Sheet Guide Utilisation
A1: MAISON 41 — GUIDE D'UTILISATION DE L'ERP — Mode d'emploi de toutes les feuilles
A3: REFERENTIELS (ne pas supprimer)
A4: Feuille | B4: Quand | C4: Comment / Ce qu'il faut saisir | D4: Point d'attention
A5: MP Referentiel | B5: Saisie annuelle | C5: Mettre a jour le prix col F (jaune) quand le fournisseur change · Tout se recalcule | D5: Saisir prix en EUR/kg
A6: Recettes | B6: Creation + validation | C6: Renseigner allergenes (cols M-R) et valeurs nutritionnelles (cols S-W) · Statut = Actif pour apparaitre dans Planning | D6: Ne modifier que si recette change
A7: Referentiel Gamme | B7: Lecture seule | C7: Nomenclature complete des references · Codes departements · Formats | D7: Reference officielle
A9: PRODUCTION (flux quotidien)
A10: Feuille | B10: Quand | C10: Comment / Ce qu'il faut saisir | D10: Point d'attention
A11: Planning | B11: Chaque jour de production | C11: Renseigner Date + Recette + Autoclave + Fraction → Nb bocaux se calcule · Passer en "En production" → Fiche Lot creee auto | D11: Statut = Termine declenche DDM
A12: Fiche Lot | B12: Pendant la production | C12: Completer T° coeur (CCP1 obligatoire) + Nb bocaux reels + Observations · Statut = Valide → Stock mis a jour auto | D12: ARCHIVER 5 ANS apres DDM
A13: DDM | B13: Automatique | C13: Saisir N° lot col A → Recette, Format, DDM se remplissent depuis Fiche Lot · Surveiller les dates proches | D13: Priorite vente si < 30j
A14: Historique Lots | B14: Bilan | C14: Saisir N° lot → tout se remplit depuis Fiche Lot · Completer CA reel + cout reel apres vente | D14: Bilan mensuel
A16: COMMERCIAL (flux ventes)
A17: Feuille | B17: Quand | C17: Comment / Ce qu'il faut saisir | D17: Point d'attention
A18: Ventes | B18: Apres chaque vente | C18: Saisir date + canal + recette + format + qte + prix · La TVA et le HT se calculent depuis Config | D18: Source KPI Dashboard
A19: Bons de Commande | B19: Avant livraison B2B | C19: Saisir client + produits · Statut "Confirme" → lot Planning cree · Statut "Livre" → Vente enregistree auto | D19: N° facture = N° BC
A20: CRM | B20: Apres chaque contact | C20: Enrichir fiche client apres chaque vente · Alerte orange si B2B > 90j sans commande | D20: Source picking Ulule
A21: CE & Associations | B21: Oct-Dec | C21: Saisir commandes collectives · Remise calculee auto selon quantite | D21: Peak Oct-Dec
A22: Marches | B22: Avant chaque marche | C22: Renseigner date + lieu + CA previsionnel · Completer CA reel apres le marche | D22: Analyse canal B2C
A24: FINANCE
A25: Feuille | B25: Quand | C25: Comment / Ce qu'il faut saisir | D25: Point d'attention
A26: Prix Vente | B26: A chaque changement | C26: Saisir uniquement col C (jaune) = TTC B2C x1 · Tout le reste se calcule | D26: PVC conseille en note survol
A27: Cout de Revient | B27: Automatique | C27: Se recalcule quand MP Referentiel ou Detail Recettes change · Verifier marge cible Config | D27: Marge < 30% = danger
A28: Previsionnel | B28: Mensuel | C28: Mettre a jour Tresorerie 13 semaines · Comparer reel vs previsionnel | D28: Presenter a la banque
A29: Compta | B29: Mensuel | C29: Saisir toutes les operations · Categories pour export expert-comptable | D29: Export CSV mensuel
A31: DDPP & QUALITE (obligations legales)
A32: Feuille | B32: Quand | C32: Comment / Ce qu'il faut saisir | D32: Point d'attention
A33: HACCP | B33: Chaque controle | C33: Enregistrer chaque point de controle · Statut NC → Action corrective obligatoire | D33: 5 ans archive minimum
A34: Plan Nettoyage | B34: Chaque nettoyage | C34: Cocher les zones nettoyees · Produit utilise · Signature operateur | D34: Controle DDPP
A35: Reclamations | B35: A chaque reclamation | C35: Enregistrer dans les 24h · Action corrective obligatoire · Critique → contacter DDPP | D35: Delai reponse J+1 si Critique
A36: Fiches Techniques | B36: A valider | C36: Completer allergenes + nutritionnels + bareme par recette · Document officiel INCO | D36: Presenter a tout controle
A37: DUERP | B37: Annuel | C37: Evaluer les risques (PxG) · Actions correctives si >=9 · Signer et dater | D37: Mise a jour annuelle obligatoire
A38: PMS | B38: Presenter a DDPP | C38: Document de reference sanitaire · Mettre a jour si procedure change | D38: Avant toute ouverture officielle

Sheet MP Referentiel
A1: MAISON 41 — REFERENTIEL MATIERES PREMIERES — Source de verite
A2: Colonne F (JAUNE) = PRIX A RENSEIGNER — Toutes les recettes se recalculent
A3: Code MP · Designation · Categorie · Unite · Fournisseur · Prix (JAUNE) · Date MaJ · Note · Recettes · Sync
A4: Code MP | B4: Designation | C4: Categorie | D4: Unite | E4: Fournisseur | F4: PRIX SAISIR ICI | G4: Date MaJ | H4: Note qualite | I4: Nb recettes | J4: Sync App | K4: Prix precedent | L4: Variation %
A5: MP01 | B5: Porc epaule desossee | C5: Viande porc | D5: kg | F5: 8.5 | G5: Mar 2026 | L5: =IFERROR(IF(OR(F5="",K5=""),"",((F5-K5)/K5)*100),"") -> #ERROR!
A6: MP02 | B6: Porc gorge (gras dur) | C6: Viande porc | D6: kg | F6: 5.5 | G6: Mar 2026 | L6: =IFERROR(IF(OR(F6="",K6=""),"",((F6-K6)/K6)*100),"") -> #ERROR!
A7: MP03 | B7: Porc foie | C7: Viande porc | D7: kg | F7: 4.5 | G7: Mar 2026 | L7: =IFERROR(IF(OR(F7="",K7=""),"",((F7-K7)/K7)*100),"") -> #ERROR!
A8: MP04 | B8: Porc couenne | C8: Viande porc | D8: kg | F8: 2.8 | G8: Mar 2026 | L8: =IFERROR(IF(OR(F8="",K8=""),"",((F8-K8)/K8)*100),"") -> #ERROR!
A9: MP05 | B9: Lardons nature sans nitrite | C9: Viande porc | D9: kg | F9: 14 | G9: Mar 2026 | L9: =IFERROR(IF(OR(F9="",K9=""),"",((F9-K9)/K9)*100),"") -> #ERROR!
A10: MP06 | B10: Saucisses Toulouse artisanales | C10: Charcuterie | D10: kg | F10: 13.5 | G10: Mar 2026 | L10: =IFERROR(IF(OR(F10="",K10=""),"",((F10-K10)/K10)*100),"") -> #ERROR!
A11: MP07 | B11: Boeuf paleron | C11: Viande boeuf | D11: kg | F11: 14.5 | G11: Mar 2026 | L11: =IFERROR(IF(OR(F11="",K11=""),"",((F11-K11)/K11)*100),"") -> #ERROR!
A12: MP08 | B12: Os a moelle boeuf | C12: Viande boeuf | D12: kg | F12: 5.5 | G12: Mar 2026 | L12: =IFERROR(IF(OR(F12="",K12=""),"",((F12-K12)/K12)*100),"") -> #ERROR!
A13: MP09 | B13: Ail frais | C13: Legumes | D13: kg | F13: 6.5 | G13: Mar 2026 | L13: =IFERROR(IF(OR(F13="",K13=""),"",((F13-K13)/K13)*100),"") -> #ERROR!
A14: MP10 | B14: Carotte | C14: Legumes | D14: kg | F14: 1.2 | G14: Mar 2026 | L14: =IFERROR(IF(OR(F14="",K14=""),"",((F14-K14)/K14)*100),"") -> #ERROR!
A15: MP11 | B15: Celeri branche | C15: Legumes | D15: kg | F15: 1.8 | G15: Mar 2026 | L15: =IFERROR(IF(OR(F15="",K15=""),"",((F15-K15)/K15)*100),"") -> #ERROR!
A16: MP12 | B16: Celeri-rave | C16: Legumes | D16: kg | F16: 2 | G16: Mar 2026 | L16: =IFERROR(IF(OR(F16="",K16=""),"",((F16-K16)/K16)*100),"") -> #ERROR!
... A77: MP73 | B77: Bocal Weck W60-160 + joint | C77: Consommable | D77: u | F77: 1.1 | G77: Mar 2026 | L77: =IFERROR(IF(OR(F77="",K77=""),"",((F77-K77)/K77)*100),"") -> #ERROR!
A78: Gorge | B78: gorge de porc | C78: Viande | D78: g | E78: cooperl | F78: 2 | G78: Mar 2026
A79: AJOUTER ICI — Prochain code : MP74
A80: MP58 | B80: Ricard | C80: Alcools | D80: kg | E80: gms | F80: 15.45 | G80: Apr 2026
A81: MP74 | B81: Ricard | C81: Alcools | D81: kg | E81: gms | F81: 15.51 | G81: Apr 2026

Sheet Recettes
A1: MAISON 41 — REFERENTIEL RECETTES
A2: 4 gammes · Recettes actives · Voir "Detail Recettes" pour les ingredients
A3: Ref. | B3: Nom commercial | C3: Gamme | D3: Format principal | E3: Rendement % | F3: Batch kg MP | G3: Temps (h) | H3: Statut | I3: Nb ing. | J3: Cout MP/kg (EUR) | K3: Date creation | L3: Gluten | M3: Oeufs | N3: Lait | O3: Sulfites | P3: Moutarde | Q3: Autres allerg. | R3: kcal/100g | S3: Prot. g/100g | T3: Lip. g/100g | U3: Gluc. g/100g | V3: Sel g/100g | W3: Sync App
A4: RC | B4: Rillettes du Chef | C4: Rillettes | D4: RR100-580 | E4: 85 | F4: 5 | G4: 3.5 | H4: Actif | I4: =IFERROR(COUNTIF('Detail Recettes'!A:A,"RC"),"") -> #ERROR! | J4: =IFERROR(SUMPRODUCT(('Detail Recettes'!A:A="RC")*'Detail Recettes'!D:D*IFERROR(INDEX('MP Referentiel'!F:F,MATCH('Detail Recettes'!B:B,'MP Referentiel'!A:A,0)),0))/5,"") -> #ERROR! | K4: Mar 2026 | L4: OK
A5: PC | B5: Pate du Chef | C5: Pates & Terrines | D5: RR100-580 | E5: 88 | F5: 5 | G5: 4 | H5: Actif | I5: =IFERROR(COUNTIF('Detail Recettes'!A:A,"PC"),"") -> #ERROR! | J5: =IFERROR(SUMPRODUCT(('Detail Recettes'!A:A="PC")*'Detail Recettes'!D:D*IFERROR(INDEX('MP Referentiel'!F:F,MATCH('Detail Recettes'!B:B,'MP Referentiel'!A:A,0)),0))/5,"") -> #ERROR! | K5: Mar 2026 | L5: OK
A6: MC | B6: Mousse du Chef | C6: Mousses | D6: RR100-370 | E6: 82 | F6: 4 | G6: 2.5 | H6: Actif | I6: =IFERROR(COUNTIF('Detail Recettes'!A:A,"MC"),"") -> #ERROR! | J6: =IFERROR(SUMPRODUCT(('Detail Recettes'!A:A="MC")*'Detail Recettes'!D:D*IFERROR(INDEX('MP Referentiel'!F:F,MATCH('Detail Recettes'!B:B,'MP Referentiel'!A:A,0)),0))/4,"") -> #ERROR! | K6: Mar 2026 | L6: OK
A7: TC | B7: Plat Traiteur du Chef | C7: Plats cuisines | D7: RR100-850 | E7: 80 | F7: 6 | G7: 3.5 | H7: Actif | I7: =IFERROR(COUNTIF('Detail Recettes'!A:A,"TC"),"") -> #ERROR! | J7: =IFERROR(SUMPRODUCT(('Detail Recettes'!A:A="TC")*'Detail Recettes'!D:D*IFERROR(INDEX('MP Referentiel'!F:F,MATCH('Detail Recettes'!B:B,'MP Referentiel'!A:A,0)),0))/6,"") -> #ERROR! | K7: Mar 2026 | L7: OK
A8: DC | B8: Dessert du Chef - Creme Vanill | C8: Desserts appertises | D8: RR100-290 | E8: 95 | F8: 4 | G8: 2 | H8: Actif | I8: =IFERROR(COUNTIF('Detail Recettes'!A:A,"DC"),"") -> #ERROR! | J8: =IFERROR(SUMPRODUCT(('Detail Recettes'!A:A="DC")*'Detail Recettes'!D:D*IFERROR(INDEX('MP Referentiel'!F:F,MATCH('Detail Recettes'!B:B,'MP Referentiel'!A:A,0)),0))/4,"") -> #ERROR! | K8: Mar 2026 | L8: OK
A9: P01 | B9: Pate de Campagne Maison 41 | C9: Pates & Terrines | D9: RR100-580 | E9: 88 | F9: 5 | G9: 4 | H9: Actif | I9: =IFERROR(COUNTIF('Detail Recettes'!A:A,"P01"),"") -> #ERROR! | J9: =IFERROR(SUMPRODUCT(('Detail Recettes'!A:A="P01")*'Detail Recettes'!D:D*IFERROR(INDEX('MP Referentiel'!F:F,MATCH('Detail Recettes'!B:B,'MP Referentiel'!A:A,0)),0))/5,"") -> #ERROR! | K9: Mar 2026 | L9: OK
A10: P02 | B10: Pate Echalote & Thym Citron | C10: Pates & Terrines | D10: RR100-580 | E10: 88 | F10: 5 | G10: 4 | H10: Actif | I10: =IFERROR(COUNTIF('Detail Recettes'!A:A,"P02"),"") -> #ERROR! | J10: =IFERROR(SUMPRODUCT(('Detail Recettes'!A:A="P02")*'Detail Recettes'!D:D*IFERROR(INDEX('MP Referentiel'!F:F,MATCH('Detail Recettes'!B:B,'MP Referentiel'!A:A,0)),0))/5,"") -> #ERROR! | K10: Mar 2026 | L10: OK
A11: P03 | B11: Pate Basque Piment d'Espelette | C11: Pates & Terrines | D11: RR100-580 | E11: 87 | F11: 5 | G11: 4.5 | H11: Actif | I11: =IFERROR(COUNTIF('Detail Recettes'!A:A,"P03"),"") -> #ERROR! | J11: =IFERROR(SUMPRODUCT(('Detail Recettes'!A:A="P03")*'Detail Recettes'!D:D*IFERROR(INDEX('MP Referentiel'!F:F,MATCH('Detail Recettes'!B:B,'MP Referentiel'!A:A,0)),0))/5,"") -> #ERROR! | K11: Mar 2026 | L11: OK
A12: P04 | B12: Pate Pleurotes & Persil Plat | C12: Pates & Terrines | D12: RR100-580 | E12: 86 | F12: 5 | G12: 4.5 | H12: Actif | I12: =IFERROR(COUNTIF('Detail Recettes'!A:A,"P04"),"") -> #ERROR! | J12: =IFERROR(SUMPRODUCT(('Detail Recettes'!A:A="P04")*'Detail Recettes'!D:D*IFERROR(INDEX('MP Referentiel'!F:F,MATCH('Detail Recettes'!B:B,'MP Referentiel'!A:A,0)),0))/5,"") -> #ERROR! | K12: Mar 2026 | L12: OK
A13: P07 | B13: Pate Chataigne Ardeche | C13: Pates & Terrines | D13: RR100-580 | E13: 87 | F13: 5 | G13: 4.5 | H13: Actif | I13: =IFERROR(COUNTIF('Detail Recettes'!A:A,"P07"),"") -> #ERROR! | J13: =IFERROR(SUMPRODUCT(('Detail Recettes'!A:A="P07")*'Detail Recettes'!D:D*IFERROR(INDEX('MP Referentiel'!F:F,MATCH('Detail Recettes'!B:B,'MP Referentiel'!A:A,0)),0))/5,"") -> #ERROR! | K13: Mar 2026 | L13: OK
A14: P49 | B14: Pate Echalotes Grises d'Anjou | C14: Pates & Terrines | D14: RR100-580 | E14: 88 | F14: 5 | G14: 4 | H14: Actif | I14: =IFERROR(COUNTIF('Detail Recettes'!A:A,"P49"),"") -> #ERROR! | J14: =IFERROR(SUMPRODUCT(('Detail Recettes'!A:A="P49")*'Detail Recettes'!D:D*IFERROR(INDEX('MP Referentiel'!F:F,MATCH('Detail Recettes'!B:B,'MP Referentiel'!A:A,0)),0))/5,"") -> #ERROR! | K14: Mar 2026 | L14: OK
A15: R41 | B15: Rillettes Classiques au Thym | C15: Rillettes | D15: RR100-580 | E15: 85 | F15: 5 | G15: 3.5 | H15: Actif | I15: =IFERROR(COUNTIF('Detail Recettes'!A:A,"R41"),"") -> #ERROR! | J15: =IFERROR(SUMPRODUCT(('Detail Recettes'!A:A="R41")*'Detail Recettes'!D:D*IFERROR(INDEX('MP Referentiel'!F:F,MATCH('Detail Recettes'!B:B,'MP Referentiel'!A:A,0)),0))/5,"") -> #ERROR! | K15: Mar 2026 | L15: OK
A16: R42 | B16: Rillettes Poireaux Confits | C16: Rillettes | D16: RR100-580 | E16: 84 | F16: 5 | G16: 4 | H16: Actif | I16: =IFERROR(COUNTIF('Detail Recettes'!A:A,"R42"),"") -> #ERROR! | J16: =IFERROR(SUMPRODUCT(('Detail Recettes'!A:A="R42")*'Detail Recettes'!D:D*IFERROR(INDEX('MP Referentiel'!F:F,MATCH('Detail Recettes'!B:B,'MP Referentiel'!A:A,0)),0))/5,"") -> #ERROR! | K16: Mar 2026 | L16: OK
A17: R43 | B17: Rillettes Gingembre & Citron | C17: Rillettes | D17: RR100-370 | E17: 85 | F17: 5 | G17: 3.5 | H17: Actif | I17: =IFERROR(COUNTIF('Detail Recettes'!A:A,"R43"),"") -> #ERROR! | J17: =IFERROR(SUMPRODUCT(('Detail Recettes'!A:A="R43")*'Detail Recettes'!D:D*IFERROR(INDEX('MP Referentiel'!F:F,MATCH('Detail Recettes'!B:B,'MP Referentiel'!A:A,0)),0))/5,"") -> #ERROR! | K17: Mar 2026 | L17: OK
A18: R44 | B18: Rillettes Poivre de Madagascar | C18: Rillettes | D18: RR100-370 | E18: 85 | F18: 5 | G18: 3.5 | H18: Actif | I18: =IFERROR(COUNTIF('Detail Recettes'!A:A,"R44"),"") -> #ERROR! | J18: =IFERROR(SUMPRODUCT(('Detail Recettes'!A:A="R44")*'Detail Recettes'!D:D*IFERROR(INDEX('MP Referentiel'!F:F,MATCH('Detail Recettes'!B:B,'MP Referentiel'!A:A,0)),0))/5,"") -> #ERROR! | K18: Mar 2026 | L18: OK
A19: R59 | B19: Rillettes Poireaux Confits Nord | C19: Rillettes | D19: RR100-370 | E19: 84 | F19: 5 | G19: 4 | H19: Actif | I19: =IFERROR(COUNTIF('Detail Recettes'!A:A,"R59"),"") -> #ERROR! | J19: =IFERROR(SUMPRODUCT(('Detail Recettes'!A:A="R59")*'Detail Recettes'!D:D*IFERROR(INDEX('MP Referentiel'!F:F,MATCH('Detail Recettes'!B:B,'MP Referentiel'!A:A,0)),0))/5,"") -> #ERROR! | K19: Mar 2026 | L19: OK
A20: R974 | B20: Rillettes Curry Vert Reunion | C20: Rillettes | D20: RR100-370 | E20: 85 | F20: 5 | G20: 3.5 | H20: Actif | I20: =IFERROR(COUNTIF('Detail Recettes'!A:A,"R974"),"") -> #ERROR! | J20: =IFERROR(SUMPRODUCT(('Detail Recettes'!A:A="R974")*'Detail Recettes'!D:D*IFERROR(INDEX('MP Referentiel'!F:F,MATCH('Detail Recettes'!B:B,'MP Referentiel'!A:A,0)),0))/5,"") -> #ERROR! | K20: Mar 2026 | L20: OK
A21: M13 | B21: Mousse Brandade de Morue | C21: Mousses | D21: RR100-370 | E21: 82 | F21: 4 | G21: 2.5 | H21: Actif | I21: =IFERROR(COUNTIF('Detail Recettes'!A:A,"M13"),"") -> #ERROR! | J21: =IFERROR(SUMPRODUCT(('Detail Recettes'!A:A="M13")*'Detail Recettes'!D:D*IFERROR(INDEX('MP Referentiel'!F:F,MATCH('Detail Recettes'!B:B,'MP Referentiel'!A:A,0)),0))/4,"") -> #ERROR! | K21: Mar 2026 | L21: OK
A22: PC01 | B22: Saucisses Lentilles Puy | C22: Plats cuisines | D22: RR100-850 | E22: 82 | F22: 6 | G22: 3 | H22: Actif | I22: =IFERROR(COUNTIF('Detail Recettes'!A:A,"PC01"),"") -> #ERROR! | J22: =IFERROR(SUMPRODUCT(('Detail Recettes'!A:A="PC01")*'Detail Recettes'!D:D*IFERROR(INDEX('MP Referentiel'!F:F,MATCH('Detail Recettes'!B:B,'MP Referentiel'!A:A,0)),0))/6,"") -> #ERROR! | K22: Mar 2026 | L22: OK
A23: PC02 | B23: Bourguignon de Boeuf | C23: Plats cuisines | D23: RR100-850 | E23: 78 | F23: 6 | G23: 4.5 | H23: Actif | I23: =IFERROR(COUNTIF('Detail Recettes'!A:A,"PC02"),"") -> #ERROR! | J23: =IFERROR(SUMPRODUCT(('Detail Recettes'!A:A="PC02")*'Detail Recettes'!D:D*IFERROR(INDEX('MP Referentiel'!F:F,MATCH('Detail Recettes'!B:B,'MP Referentiel'!A:A,0)),0))/6,"") -> #ERROR! | K23: Mar 2026 | L23: OK
A24: PC03 | B24: Pot-au-Feu de Boeuf | C24: Plats cuisines | D24: RR100-1050 | E24: 80 | F24: 6 | G24: 5 | H24: Actif | I24: =IFERROR(COUNTIF('Detail Recettes'!A:A,"PC03"),"") -> #ERROR! | J24: =IFERROR(SUMPRODUCT(('Detail Recettes'!A:A="PC03")*'Detail Recettes'!D:D*IFERROR(INDEX('MP Referentiel'!F:F,MATCH('Detail Recettes'!B:B,'MP Referentiel'!A:A,0)),0))/6,"") -> #ERROR! | K24: Mar 2026 | L24: OK
A25: PC04 | B25: Saute Porc & Puree | C25: Plats cuisines | D25: RR100-850 | E25: 83 | F25: 6 | G25: 3 | H25: Actif | I25: =IFERROR(COUNTIF('Detail Recettes'!A:A,"PC04"),"") -> #ERROR! | J25: =IFERROR(SUMPRODUCT(('Detail Recettes'!A:A="PC04")*'Detail Recettes'!D:D*IFERROR(INDEX('MP Referentiel'!F:F,MATCH('Detail Recettes'!B:B,'MP Referentiel'!A:A,0)),0))/6,"") -> #ERROR! | K25: Mar 2026 | L25: OK
A26: T31 | B26: Cassoulet Maison 41 | C26: Plats cuisines | D26: RR100-850 | E26: 80 | F26: 6 | G26: 4 | H26: Actif | I26: =IFERROR(COUNTIF('Detail Recettes'!A:A,"T31"),"") -> #ERROR! | J26: =IFERROR(SUMPRODUCT(('Detail Recettes'!A:A="T31")*'Detail Recettes'!D:D*IFERROR(INDEX('MP Referentiel'!F:F,MATCH('Detail Recettes'!B:B,'MP Referentiel'!A:A,0)),0))/6,"") -> #ERROR! | K26: Mar 2026 | L26: OK
A27: S64 | B27: Garbure Bearnaise | C27: Soupes | D27: RR100-850 | E27: 85 | F27: 5 | G27: 3 | H27: Actif | I27: =IFERROR(COUNTIF('Detail Recettes'!A:A,"S64"),"") -> #ERROR! | J27: =IFERROR(SUMPRODUCT(('Detail Recettes'!A:A="S64")*'Detail Recettes'!D:D*IFERROR(INDEX('MP Referentiel'!F:F,MATCH('Detail Recettes'!B:B,'MP Referentiel'!A:A,0)),0))/5,"") -> #ERROR! | K27: Mar 2026 | L27: OK
A28: D01 | B28: Creme Oeufs Vanille Bourbon | C28: Desserts appertises | D28: RR100-290 | E28: 95 | F28: 4 | G28: 2 | H28: Actif | I28: =IFERROR(COUNTIF('Detail Recettes'!A:A,"D01"),"") -> #ERROR! | J28: =IFERROR(SUMPRODUCT(('Detail Recettes'!A:A="D01")*'Detail Recettes'!D:D*IFERROR(INDEX('MP Referentiel'!F:F,MATCH('Detail Recettes'!B:B,'MP Referentiel'!A:A,0)),0))/4,"") -> #ERROR! | K28: Mar 2026 | L28: OK
A29: D02 | B29: Creme Chocolat Noir 70% | C29: Desserts appertises | D29: RR100-290 | E29: 95 | F29: 4 | G29: 2 | H29: Actif | I29: =IFERROR(COUNTIF('Detail Recettes'!A:A,"D02"),"") -> #ERROR! | J29: =IFERROR(SUMPRODUCT(('Detail Recettes'!A:A="D02")*'Detail Recettes'!D:D*IFERROR(INDEX('MP Referentiel'!F:F,MATCH('Detail Recettes'!B:B,'MP Referentiel'!A:A,0)),0))/4,"") -> #ERROR! | K29: Mar 2026 | L29: OK
A30: D03 | B30: Creme Caramel Renversee | C30: Desserts appertises | D30: RR100-290 | E30: 94 | F30: 4 | G30: 2.5 | H30: Actif | I30: =IFERROR(COUNTIF('Detail Recettes'!A:A,"D03"),"") -> #ERROR! | J30: =IFERROR(SUMPRODUCT(('Detail Recettes'!A:A="D03")*'Detail Recettes'!D:D*IFERROR(INDEX('MP Referentiel'!F:F,MATCH('Detail Recettes'!B:B,'MP Referentiel'!A:A,0)),0))/4,"") -> #ERROR! | K30: Mar 2026 | L30: OK
A31: D04 | B31: Riz au Lait Cannelle & Orange | C31: Desserts appertises | D31: RR100-370 | E31: 92 | F31: 4 | G31: 1.5 | H31: Actif | I31: =IFERROR(COUNTIF('Detail Recettes'!A:A,"D04"),"") -> #ERROR! | J31: =IFERROR(SUMPRODUCT(('Detail Recettes'!A:A="D04")*'Detail Recettes'!D:D*IFERROR(INDEX('MP Referentiel'!F:F,MATCH('Detail Recettes'!B:B,'MP Referentiel'!A:A,0)),0))/4,"") -> #ERROR! | K31: Mar 2026 | L31: OK
A32: D29 | B32: Far Breton aux Pruneaux | C32: Desserts appertises | D32: RR100-370 | E32: 88 | F32: 4 | G32: 2 | H32: Actif | I32: =IFERROR(COUNTIF('Detail Recettes'!A:A,"D29"),"") -> #ERROR! | J32: =IFERROR(SUMPRODUCT(('Detail Recettes'!A:A="D29")*'Detail Recettes'!D:D*IFERROR(INDEX('MP Referentiel'!F:F,MATCH('Detail Recettes'!B:B,'MP Referentiel'!A:A,0)),0))/4,"") -> #ERROR! | K32: Mar 2026 | L32: OK
A33: RC | B33: Rillettes du Chef | C33: Rillettes | D33: En développement | G33: 115 | H33: 24 | Q33: 46110 | R33: 46110
A34: NOUVELLES RECETTES — ajouter ici + renseigner les ingredients dans "Detail Recettes"
A35: R51 | B35: Rillettes aux Ricard | C35: Rillettes | E35: 95 | H35: Actif | K35: 46113

Sheet Detail Recettes
A1: MAISON 41 — DETAIL RECETTES — Ingredients par recette
A2: Source du cout MP et du calcul des besoins d'achat depuis le planning
A3: Ref recette · Code MP · Designation · Quantite · Unite · Prix MP · Cout ligne · % du cout total
A4: Ref. recette | B4: Code MP | C4: Designation MP | D4: Qte par batch | E4: Unite | F4: Prix MP (EUR) | G4: Cout ligne (EUR) | H4: % cout total | I4: Gamme recette | J4: Batch (kg)
A5: PC | B5: MP01 | C5: Epaule porc desossee | D5: 0.54 | E5: kg | F5: =IFERROR(INDEX('MP Referentiel'!F:F,MATCH(B14,'MP Referentiel'!A:A,0)),"") -> #ERROR! | G5: =IFERROR(D14*F14,"") -> #ERROR! | H5: =IFERROR(G14/SUMPRODUCT(('Detail Recettes'!A$5:A$183=A14)*'Detail Recettes'!G$5:G$183),"") -> #ERROR! | I5: =IFERROR(INDEX(Recettes!C:C,MATCH(A14,Recettes!A:A,0)),"") -> #ERROR! | J5: =IFERROR(INDEX(Recettes!F:F,MATCH(A14,Recettes!A:A,0)),"") -> #ERROR!
A6: PC | B6: MP02 | C6: Gorge porc | D6: 0.16 | E6: kg | F6: =IFERROR(INDEX('MP Referentiel'!F:F,MATCH(B15,'MP Referentiel'!A:A,0)),"") -> #ERROR! | G6: =IFERROR(D15*F15,"") -> #ERROR! | H6: =IFERROR(G15/SUMPRODUCT(('Detail Recettes'!A$5:A$183=A15)*'Detail Recettes'!G$5:G$183),"") -> #ERROR! | I6: =IFERROR(INDEX(Recettes!C:C,MATCH(A15,Recettes!A:A,0)),"") -> #ERROR! | J6: =IFERROR(INDEX(Recettes!F:F,MATCH(A15,Recettes!A:A,0)),"") -> #ERROR!
A7: PC | B7: MP03 | C7: Foie porc | D7: 0.08 | E7: kg | F7: =IFERROR(INDEX('MP Referentiel'!F:F,MATCH(B16,'MP Referentiel'!A:A,0)),"") -> #ERROR! | G7: =IFERROR(D16*F16,"") -> #ERROR! | H7: =IFERROR(G16/SUMPRODUCT(('Detail Recettes'!A$5:A$183=A16)*'Detail Recettes'!G$5:G$183),"") -> #ERROR! | I7: =IFERROR(INDEX(Recettes!C:C,MATCH(A16,Recettes!A:A,0)),"") -> #ERROR! | J7: =IFERROR(INDEX(Recettes!F:F,MATCH(A16,Recettes!A:A,0)),"") -> #ERROR!
A8: PC | B8: MP34 | C8: Oeufs frais entiers | D8: 0.06 | E8: kg | F8: =IFERROR(INDEX('MP Referentiel'!F:F,MATCH(B17,'MP Referentiel'!A:A,0)),"") -> #ERROR! | G8: =IFERROR(D17*F17,"") -> #ERROR! | H8: =IFERROR(G17/SUMPRODUCT(('Detail Recettes'!A$5:A$183=A17)*'Detail Recettes'!G$5:G$183),"") -> #ERROR! | I8: =IFERROR(INDEX(Recettes!C:C,MATCH(A17,Recettes!A:A,0)),"") -> #ERROR! | J8: =IFERROR(INDEX(Recettes!F:F,MATCH(A17,Recettes!A:A,0)),"") -> #ERROR!
A9: PC | B9: MP16 | C9: Oignon jaune | D9: 0.04 | E9: kg | F9: =IFERROR(INDEX('MP Referentiel'!F:F,MATCH(B18,'MP Referentiel'!A:A,0)),"") -> #ERROR! | G9: =IFERROR(D18*F18,"") -> #ERROR! | H9: =IFERROR(G18/SUMPRODUCT(('Detail Recettes'!A$5:A$183=A18)*'Detail Recettes'!G$5:G$183),"") -> #ERROR! | I9: =IFERROR(INDEX(Recettes!C:C,MATCH(A18,Recettes!A:A,0)),"") -> #ERROR! | J9: =IFERROR(INDEX(Recettes!F:F,MATCH(A18,Recettes!A:A,0)),"") -> #ERROR!
A10: PC | B10: MP60 | C10: Cognac / Armagnac | D10: 0.02 | E10: L | F10: =IFERROR(INDEX('MP Referentiel'!F:F,MATCH(B19,'MP Referentiel'!A:A,0)),"") -> #ERROR! | G10: =IFERROR(D19*F19,"") -> #ERROR! | H10: =IFERROR(G19/SUMPRODUCT(('Detail Recettes'!A$5:A$183=A19)*'Detail Recettes'!G$5:G$183),"") -> #ERROR! | I10: =IFERROR(INDEX(Recettes!C:C,MATCH(A19,Recettes!A:A,0)),"") -> #ERROR! | J10: =IFERROR(INDEX(Recettes!F:F,MATCH(A19,Recettes!A:A,0)),"") -> #ERROR!
A11: PC | B11: MP51 | C11: Sel fin | D11: 0.015 | E11: kg | F11: =IFERROR(INDEX('MP Referentiel'!F:F,MATCH(B20,'MP Referentiel'!A:A,0)),"") -> #ERROR! | G11: =IFERROR(D20*F20,"") -> #ERROR! | H11: =IFERROR(G20/SUMPRODUCT(('Detail Recettes'!A$5:A$183=A20)*'Detail Recettes'!G$5:G$183),"") -> #ERROR! | I11: =IFERROR(INDEX(Recettes!C:C,MATCH(A20,Recettes!A:A,0)),"") -> #ERROR! | J11: =IFERROR(INDEX(Recettes!F:F,MATCH(A20,Recettes!A:A,0)),"") -> #ERROR!
A12: PC | B12: MP50 | C12: Poivre noir moulu | D12: 0.003 | E12: kg | F12: =IFERROR(INDEX('MP Referentiel'!F:F,MATCH(B21,'MP Referentiel'!A:A,0)),"") -> #ERROR! | G12: =IFERROR(D21*F21,"") -> #ERROR! | H12: =IFERROR(G21/SUMPRODUCT(('Detail Recettes'!A$5:A$183=A21)*'Detail Recettes'!G$5:G$183),"") -> #ERROR! | I12: =IFERROR(INDEX(Recettes!C:C,MATCH(A21,Recettes!A:A,0)),"") -> #ERROR! | J12: =IFERROR(INDEX(Recettes!F:F,MATCH(A21,Recettes!A:A,0)),"") -> #ERROR!
A13: PC | B13: MP25 | C13: Quatre-epices | D13: 0.001 | E13: kg | F13: =IFERROR(INDEX('MP Referentiel'!F:F,MATCH(B22,'MP Referentiel'!A:A,0)),"") -> #ERROR! | G13: =IFERROR(D22*F22,"") -> #ERROR! | H13: =IFERROR(G22/SUMPRODUCT(('Detail Recettes'!A$5:A$183=A22)*'Detail Recettes'!G$5:G$183),"") -> #ERROR! | I13: =IFERROR(INDEX(Recettes!C:C,MATCH(A22,Recettes!A:A,0)),"") -> #ERROR! | J13: =IFERROR(INDEX(Recettes!F:F,MATCH(A22,Recettes!A:A,0)),"") -> #ERROR!
A14: PC | B14: MP42 | C14: Thym seche | D14: 0.003 | E14: kg | F14: =IFERROR(INDEX('MP Referentiel'!F:F,MATCH(B23,'MP Referentiel'!A:A,0)),"") -> #ERROR! | G14: =IFERROR(D23*F23,"") -> #ERROR! | H14: =IFERROR(G23/SUMPRODUCT(('Detail Recettes'!A$5:A$183=A23)*'Detail Recettes'!G$5:G$183),"") -> #ERROR! | I14: =IFERROR(INDEX(Recettes!C:C,MATCH(A23,Recettes!A:A,0)),"") -> #ERROR! | J14: =IFERROR(INDEX(Recettes!F:F,MATCH(A23,Recettes!A:A,0)),"") -> #ERROR!
A15: PC | B15: MP39 | C15: Laurier | D15: 0.002 | E15: kg | F15: =IFERROR(INDEX('MP Referentiel'!F:F,MATCH(B24,'MP Referentiel'!A:A,0)),"") -> #ERROR! | G15: =IFERROR(D24*F24,"") -> #ERROR! | H15: =IFERROR(G24/SUMPRODUCT(('Detail Recettes'!A$5:A$183=A24)*'Detail Recettes'!G$5:G$183),"") -> #ERROR! | I15: =IFERROR(INDEX(Recettes!C:C,MATCH(A24,Recettes!A:A,0)),"") -> #ERROR! | J15: =IFERROR(INDEX(Recettes!F:F,MATCH(A24,Recettes!A:A,0)),"") -> #ERROR!
A16: MC | B16: MP03 | C16: Foie porc | D16: 0.52 | E16: kg | F16: =IFERROR(INDEX('MP Referentiel'!F:F,MATCH(B25,'MP Referentiel'!A:A,0)),"") -> #ERROR! | G16: =IFERROR(D25*F25,"") -> #ERROR! | H16: =IFERROR(G25/SUMPRODUCT(('Detail Recettes'!A$5:A$183=A25)*'Detail Recettes'!G$5:G$183),"") -> #ERROR! | I16: =IFERROR(INDEX(Recettes!C:C,MATCH(A25,Recettes!A:A,0)),"") -> #ERROR! | J16: =IFERROR(INDEX(Recettes!F:F,MATCH(A25,Recettes!A:A,0)),"") -> #ERROR!
... A174: D29 | B174: MP28 | C174: Beurre doux | D174: 0.08 | E174: kg | F174: =IFERROR(INDEX('MP Referentiel'!F:F,MATCH(B183,'MP Referentiel'!A:A,0)),"") -> #ERROR! | G174: =IFERROR(D183*F183,"") -> #ERROR! | H174: =IFERROR(G183/SUMPRODUCT(('Detail Recettes'!A$5:A$183=A183)*'Detail Recettes'!G$5:G$183),"") -> #ERROR! | I174: =IFERROR(INDEX(Recettes!C:C,MATCH(A183,Recettes!A:A,0)),"") -> #ERROR! | J174: =IFERROR(INDEX(Recettes!F:F,MATCH(A183,Recettes!A:A,0)),"") -> #ERROR!
A175: R51 | B175: MP01 | D175: 1 | E175: kg
A176: R51
F177: =IFERROR(INDEX('MP Referentiel'!F:F,MATCH(B186,'MP Referentiel'!A:A,0)),"") -> #ERROR! | G177: =IFERROR(D186*F186,"") -> #ERROR!
F178: =IFERROR(INDEX('MP Referentiel'!F:F,MATCH(B187,'MP Referentiel'!A:A,0)),"") -> #ERROR! | G178: =IFERROR(D187*F187,"") -> #ERROR!
F179: =IFERROR(INDEX('MP Referentiel'!F:F,MATCH(B188,'MP Referentiel'!A:A,0)),"") -> #ERROR! | G179: =IFERROR(D188*F188,"") -> #ERROR!
F180: =IFERROR(INDEX('MP Referentiel'!F:F,MATCH(B189,'MP Referentiel'!A:A,0)),"") -> #ERROR! | G180: =IFERROR(D189*F189,"") -> #ERROR!
F181: =IFERROR(INDEX('MP Referentiel'!F:F,MATCH(B190,'MP Referentiel'!A:A,0)),"") -> #ERROR! | G181: =IFERROR(D190*F190,"") -> #ERROR!
F182: =IFERROR(INDEX('MP Referentiel'!F:F,MATCH(B191,'MP Referentiel'!A:A,0)),"") -> #ERROR! | G182: =IFERROR(D191*F191,"") -> #ERROR!
F183: =IFERROR(INDEX('MP Referentiel'!F:F,MATCH(B192,'MP Referentiel'!A:A,0)),"") -> #ERROR! | G183: =IFERROR(D192*F192,"") -> #ERROR!
F184: =IFERROR(INDEX('MP Referentiel'!F:F,MATCH(B193,'MP Referentiel'!A:A,0)),"") -> #ERROR! | G184: =IFERROR(D193*F193,"") -> #ERROR!
F185: =IFERROR(INDEX('MP Referentiel'!F:F,MATCH(B194,'MP Referentiel'!A:A,0)),"") -> #ERROR! | G185: =IFERROR(D194*F194,"") -> #ERROR!
F186: =IFERROR(INDEX('MP Referentiel'!F:F,MATCH(B195,'MP Referentiel'!A:A,0)),"") -> #ERROR! | G186: =IFERROR(D195*F195,"") -> #ERROR!
F187: =IFERROR(INDEX('MP Referentiel'!F:F,MATCH(B196,'MP Referentiel'!A:A,0)),"") -> #ERROR! | G187: =IFERROR(D196*F196,"") -> #ERROR!
F188: =IFERROR(INDEX('MP Referentiel'!F:F,MATCH(B197,'MP Referentiel'!A:A,0)),"") -> #ERROR! | G188: =IFERROR(D197*F197,"") -> #ERROR!
... F276: =IFERROR(INDEX('MP Referentiel'!F:F,MATCH(B285,'MP Referentiel'!A:A,0)),"") -> #ERROR! | G276: =IFERROR(D285*F285,"") -> #ERROR!

Sheet Recette Vierge
A1: MAISON 41 — RECETTE VIERGE — Dupliquer cet onglet · Renommer avec le code produit
A2: Mode d'emploi : Fichier > Copier · Ou clic droit onglet > Dupliquer · Renommer ex: R45
A4: IDENTITE PRODUIT
A5: Code produit | B5: Ex: R45, P05, MC2, D05 | C5: Code unique — format Gamme+Dept ou Gamme+Num
A6: Nom commercial | B6: Ex: Rillettes de Canard au Cepes | C6: Nom sur etiquette et en vente
A7: Gamme | C7: Choisir : Pates/Rillettes/Mousses/Plats/Desserts/Soupes
A8: Format Weck principal | C8: Format le plus vendu pour cette recette
A9: Rendement (%) | C9: Ex: 85 = 850g de produit fini pour 1kg de MP
A10: Batch production (kg MP) | C10: Quantite MP pour 1 lot complet
A11: Temps total (h) | C11: Preparation + cuisson + sterilisation
A12: Statut | B12: En developpement | C12: En developpement / Actif / Archive
A13: Validee par | C13: Nom + date de validation recette
A14: Date creation
A15: Version | B15: V1.0 | C15: Incrementer a chaque modification recette
A18: INGREDIENTS (batch complet)
A19: Code MP | B19: Designation | C19: Quantite | D19: Unite | E19: Prix/unite EUR | F19: Cout ligne EUR
B20: =IFERROR(INDEX('MP Referentiel'!B:B,MATCH(A20,'MP Referentiel'!A:A,0)),"") -> #ERROR! | D20: kg | E20: =IFERROR(INDEX('MP Referentiel'!F:F,MATCH(A20,'MP Referentiel'!A:A,0)),"") -> #ERROR! | F20: =IFERROR(C20*E20,"") -> #ERROR!
B21: =IFERROR(INDEX('MP Referentiel'!B:B,MATCH(A21,'MP Referentiel'!A:A,0)),"") -> #ERROR! | D21: kg | E21: =IFERROR(INDEX('MP Referentiel'!F:F,MATCH(A21,'MP Referentiel'!A:A,0)),"") -> #ERROR! | F21: =IFERROR(C21*E21,"") -> #ERROR!
B22: =IFERROR(INDEX('MP Referentiel'!B:B,MATCH(A22,'MP Referentiel'!A:A,0)),"") -> #ERROR! | D22: kg | E22: =IFERROR(INDEX('MP Referentiel'!F:F,MATCH(A22,'MP Referentiel'!A:A,0)),"") -> #ERROR! | F22: =IFERROR(C22*E22,"") -> #ERROR!
B23: =IFERROR(INDEX('MP Referentiel'!B:B,MATCH(A23,'MP Referentiel'!A:A,0)),"") -> #ERROR! | D23: kg | E23: =IFERROR(INDEX('MP Referentiel'!F:F,MATCH(A23,'MP Referentiel'!A:A,0)),"") -> #ERROR! | F23: =IFERROR(C23*E23,"") -> #ERROR!
B24: =IFERROR(INDEX('MP Referentiel'!B:B,MATCH(A24,'MP Referentiel'!A:A,0)),"") -> #ERROR! | D24: kg | E24: =IFERROR(INDEX('MP Referentiel'!F:F,MATCH(A24,'MP Referentiel'!A:A,0)),"") -> #ERROR! | F24: =IFERROR(C24*E24,"") -> #ERROR!
B25: =IFERROR(INDEX('MP Referentiel'!B:B,MATCH(A25,'MP Referentiel'!A:A,0)),"") -> #ERROR! | D25: kg | E25: =IFERROR(INDEX('MP Referentiel'!F:F,MATCH(A25,'MP Referentiel'!A:A,0)),"") -> #ERROR! | F25: =IFERROR(C25*E25,"") -> #ERROR!
B26: =IFERROR(INDEX('MP Referentiel'!B:B,MATCH(A26,'MP Referentiel'!A:A,0)),"") -> #ERROR! | D26: kg | E26: =IFERROR(INDEX('MP Referentiel'!F:F,MATCH(A26,'MP Referentiel'!A:A,0)),"") -> #ERROR! | F26: =IFERROR(C26*E26,"") -> #ERROR!
B27: =IFERROR(INDEX('MP Referentiel'!B:B,MATCH(A27,'MP Referentiel'!A:A,0)),"") -> #ERROR! | D27: kg | E27: =IFERROR(INDEX('MP Referentiel'!F:F,MATCH(A27,'MP Referentiel'!A:A,0)),"") -> #ERROR! | F27: =IFERROR(C27*E27,"") -> #ERROR!
B28: =IFERROR(INDEX('MP Referentiel'!B:B,MATCH(A28,'MP Referentiel'!A:A,0)),"") -> #ERROR! | D28: kg | E28: =IFERROR(INDEX('MP Referentiel'!F:F,MATCH(A28,'MP Referentiel'!A:A,0)),"") -> #ERROR! | F28: =IFERROR(C28*E28,"") -> #ERROR!
B29: =IFERROR(INDEX('MP Referentiel'!B:B,MATCH(A29,'MP Referentiel'!A:A,0)),"") -> #ERROR! | D29: kg | E29: =IFERROR(INDEX('MP Referentiel'!F:F,MATCH(A29,'MP Referentiel'!A:A,0)),"") -> #ERROR! | F29: =IFERROR(C29*E29,"") -> #ERROR!
B30: =IFERROR(INDEX('MP Referentiel'!B:B,MATCH(A30,'MP Referentiel'!A:A,0)),"") -> #ERROR! | D30: kg | E30: =IFERROR(INDEX('MP Referentiel'!F:F,MATCH(A30,'MP Referentiel'!A:A,0)),"") -> #ERROR! | F30: =IFERROR(C30*E30,"") -> #ERROR!
B31: =IFERROR(INDEX('MP Referentiel'!B:B,MATCH(A31,'MP Referentiel'!A:A,0)),"") -> #ERROR! | D31: kg | E31: =IFERROR(INDEX('MP Referentiel'!F:F,MATCH(A31,'MP Referentiel'!A:A,0)),"") -> #ERROR! | F31: =IFERROR(C31*E31,"") -> #ERROR!
... B39: =IFERROR(INDEX('MP Referentiel'!B:B,MATCH(A39,'MP Referentiel'!A:A,0)),"") -> #ERROR! | D39: kg | E39: =IFERROR(INDEX('MP Referentiel'!F:F,MATCH(A39,'MP Referentiel'!A:A,0)),"") -> #ERROR! | F39: =IFERROR(C39*E39,"") -> #ERROR!
A41: TOTAL COUT MP | F41: =SUM(F20:F39) -> #ERROR!

Sheet Referentiel Gamme
A1: MAISON 41 — REFERENTIEL GAMME & DEPARTEMENTS — Gamme Du Chef + references
A2: RC · PC · MC · TC · DC = Gamme Du Chef · R__ P__ M__ T__ D__ S__ = Gamme Departements
A4: GAMME DU CHEF — References fondatrices signees Alexandre
A5: Code | B5: Nom | C5: Gamme | D5: Statut | E5: Description | F5: Formats recommandes | G5: Score | H5: Cout MP/kg
A6: RC | B6: Rillettes du Chef | C6: Rillettes | D6: Actif | E6: Signature Alexandre | F6: Tous formats RR100 + W60 | G6: 10 | H6: 6.1
A7: PC | B7: Pate du Chef | C7: Pates & Terrines | D7: Actif | E7: Signature Alexandre | F7: Tous formats RR100 + W60 | G7: 10 | H7: 5.79
A8: MC | B8: Mousse du Chef | C8: Mousses | D8: Actif | E8: Signature Alexandre | F8: Tous formats RR100 + W60 | G8: 10 | H8: 4.97
A9: TC | B9: Plat Traiteur du Chef | C9: Plats cuisines | D9: Actif | E9: Signature Alexandre | F9: Tous formats RR100 + W60 | G9: 10 | H9: 8.29
A10: DC | B10: Dessert du Chef | C10: Desserts appertises | D10: Actif | E10: Signature Alexandre | F10: Tous formats RR100 + W60 | G10: 10 | H10: 1.48

Sheet Prix Vente
A1: MAISON 41 — GRILLE TARIFAIRE — 1 seule saisie TTC B2C · Welcome Pack · Early Bird Ulule -15%
A2: Cellule JAUNE = seule saisie · Vert = calcule · Bleu = notre prix HT pro
A3: REGLE : PVC conseille au pro TOUJOURS > notre prix TTC B2C
A4: Gamme | B4: Format Weck | C4: B TO C MARCHES (TTC) | G4: E-COMMERCE (TTC) | J4: RESTAURANTS (HT) | M4: EPICERIES FINES (HT) | P4: HOTELS / AIRBNB (HT) | S4: GMS (HT) | V4: Marge directe | W4: WELCOME PACK TTC | X4: EARLY BIRD -15% Ulule
C5: x1 SAISIR | D5: x3 -5% | E5: x6 -8% | F5: x20 -12% | G5: x1 | H5: x3 -3% | I5: x6 -6% | J5: x3 | K5: x10 | L5: x24 | M5: x6 | N5: x12 | O5: x24 | P5: x6 | Q5: x12 | R5: x24 | S5: x100 | T5: x200 | U5: x500 | V5: %
A7: PATES & TERRINES — TVA 5%
A8: Pates & Terrines | B8: RR100-290 | C8: 5.9 | D8: =IFERROR(ROUND(C8*0.95,2),"") -> #ERROR! | E8: =IFERROR(ROUND(C8*0.92,2),"") -> #ERROR! | F8: =IFERROR(ROUND(C8*0.88,2),"") -> #ERROR! | G8: =IFERROR(ROUND(C8*1,2),"") -> #ERROR! | H8: =IFERROR(ROUND(C8*0.97,2),"") -> #ERROR! | I8: =IFERROR(ROUND(C8*0.94,2),"") -> #ERROR! | J8: =IFERROR(ROUND((C8/IFERROR(INDEX(Config!B:B,MATCH("TVA "&A8,Config!A:A,0)),1.055))*0.55,2),"") -> #ERROR! | K8: =IFERROR(ROUND((C8/IFERROR(INDEX(Config!B:B,MATCH("TVA "&A8,Config!A:A,0)),1.055))*0.48,2),"") -> #ERROR! | L8: =IFERROR(ROUND((C8/IFERROR(INDEX(Config!B:B,MATCH("TVA "&A8,Config!A:A,0)),1.055))*0.42,2),"") -> #ERROR! | M8: =IFERROR(ROUND((C8/IFERROR(INDEX(Config!B:B,MATCH("TVA "&A8,Config!A:A,0)),1.055))*0.58,2),"") -> #ERROR! | N8: =IFERROR(ROUND((C8/IFERROR(INDEX(Config!B:B,MATCH("TVA "&A8,Config!A:A,0)),1.055))*0.52,2),"") -> #ERROR! | O8: =IFERROR(ROUND((C8/IFERROR(INDEX(Config!B:B,MATCH("TVA "&A8,Config!A:A,0)),1.055))*0.52,2),"") -> #ERROR! | P8: =IFERROR(ROUND((C8/IFERROR(INDEX(Config!B:B,MATCH("TVA "&A8,Config!A:A,0)),1.055))*0.55,2),"") -> #ERROR! | Q8: =IFERROR(ROUND((C8/IFERROR(INDEX(Config!B:B,MATCH("TVA "&A8,Config!A:A,0)),1.055))*0.5,2),"") -> #ERROR! | R8: =IFERROR(ROUND((C8/IFERROR(INDEX(Config!B:B,MATCH("TVA "&A8,Config!A:A,0)),1.055))*0.5,2),"") -> #ERROR! | S8: =IFERROR(ROUND((C8/IFERROR(INDEX(Config!B:B,MATCH("TVA "&A8,Config!A:A,0)),1.055))*0.62,2),"") -> #ERROR! | T8: =IFERROR(ROUND((C8/IFERROR(INDEX(Config!B:B,MATCH("TVA "&A8,Config!A:A,0)),1.055))*0.58,2),"") -> #ERROR! | U8: =IFERROR(ROUND((C8/IFERROR(INDEX(Config!B:B,MATCH("TVA "&A8,Config!A:A,0)),1.055))*0.58,2),"") -> #ERROR! | V8: =IFERROR(((C8/IFERROR(INDEX(Config!B:B,MATCH("TVA "&A8,Config!A:A,0)),1.055))-IFERROR(INDEX('Cout de Revient'!I:I,MATCH(B8,'Cout de Revient'!C:C,0)),0))/(C8/IFERROR(INDEX(Config!B:B,MATCH("TVA "&A8,Config!A:A,0)),1.055)),"") -> #ERROR! | W8: =IFERROR(C8,"") -> #ERROR! | X8: =IFERROR(ROUND(C8*0.85,2),"") -> #ERROR!
A9: Pates & Terrines | B9: RR100-370 | C9: 7.5 | D9: =IFERROR(ROUND(C9*0.95,2),"") -> #ERROR! | E9: =IFERROR(ROUND(C9*0.92,2),"") -> #ERROR! | F9: =IFERROR(ROUND(C9*0.88,2),"") -> #ERROR! | G9: =IFERROR(ROUND(C9*1,2),"") -> #ERROR! | H9: =IFERROR(ROUND(C9*0.97,2),"") -> #ERROR! | I9: =IFERROR(ROUND(C9*0.94,2),"") -> #ERROR! | J9: =IFERROR(ROUND((C9/IFERROR(INDEX(Config!B:B,MATCH("TVA "&A9,Config!A:A,0)),1.055))*0.55,2),"") -> #ERROR! | K9: =IFERROR(ROUND((C9/IFERROR(INDEX(Config!B:B,MATCH("TVA "&A9,Config!A:A,0)),1.055))*0.48,2),"") -> #ERROR! | L9: =IFERROR(ROUND((C9/IFERROR(INDEX(Config!B:B,MATCH("TVA "&A9,Config!A:A,0)),1.055))*0.42,2),"") -> #ERROR! | M9: =IFERROR(ROUND((C9/IFERROR(INDEX(Config!B:B,MATCH("TVA "&A9,Config!A:A,0)),1.055))*0.58,2),"") -> #ERROR! | N9: =IFERROR(ROUND((C9/IFERROR(INDEX(Config!B:B,MATCH("TVA "&A9,Config!A:A,0)),1.055))*0.52,2),"") -> #ERROR! | O9: =IFERROR(ROUND((C9/IFERROR(INDEX(Config!B:B,MATCH("TVA "&A9,Config!A:A,0)),1.055))*0.52,2),"") -> #ERROR! | P9: =IFERROR(ROUND((C9/IFERROR(INDEX(Config!B:B,MATCH("TVA "&A9,Config!A:A,0)),1.055))*0.55,2),"") -> #ERROR! | Q9: =IFERROR(ROUND((C9/IFERROR(INDEX(Config!B:B,MATCH("TVA "&A9,Config!A:A,0)),1.055))*0.5,2),"") -> #ERROR! | R9: =IFERROR(ROUND((C9/IFERROR(INDEX(Config!B:B,MATCH("TVA "&A9,Config!A:A,0)),1.055))*0.5,2),"") -> #ERROR! | S9: =IFERROR(ROUND((C9/IFERROR(INDEX(Config!B:B,MATCH("TVA "&A9,Config!A:A,0)),1.055))*0.62,2),"") -> #ERROR! | T9: =IFERROR(ROUND((C9/IFERROR(INDEX(Config!B:B,MATCH("TVA "&A9,Config!A:A,0)),1.055))*0.58,2),"") -> #ERROR! | U9: =IFERROR(ROUND((C9/IFERROR(INDEX(Config!B:B,MATCH("TVA "&A9,Config!A:A,0)),1.055))*0.58,2),"") -> #ERROR! | V9: =IFERROR(((C9/IFERROR(INDEX(Config!B:B,MATCH("TVA "&A9,Config!A:A,0)),1.055))-IFERROR(INDEX('Cout de Revient'!I:I,MATCH(B9,'Cout de Revient'!C:C,0)),0))/(C9/IFERROR(INDEX(Config!B:B,MATCH("TVA "&A9,Config!A:A,0)),1.055)),"") -> #ERROR! | W9: =IFERROR(C9,"") -> #ERROR! | X9: =IFERROR(ROUND(C9*0.85,2),"") -> #ERROR!
A10: Pates & Terrines | B10: RR100-580 | C10: 9.9 | D10: =IFERROR(ROUND(C10*0.95,2),"") -> #ERROR! | E10: =IFERROR(ROUND(C10*0.92,2),"") -> #ERROR! | F10: =IFERROR(ROUND(C10*0.88,2),"") -> #ERROR! | G10: =IFERROR(ROUND(C10*1,2),"") -> #ERROR! | H10: =IFERROR(ROUND(C10*0.97,2),"") -> #ERROR! | I10: =IFERROR(ROUND(C10*0.94,2),"") -> #ERROR! | J10: =IFERROR(ROUND((C10/IFERROR(INDEX(Config!B:B,MATCH("TVA "&A10,Config!A:A,0)),1.055))*0.55,2),"") -> #ERROR! | K10: =IFERROR(ROUND((C10/IFERROR(INDEX(Config!B:B,MATCH("TVA "&A10,Config!A:A,0)),1.055))*0.48,2),"") -> #ERROR! | L10: =IFERROR(ROUND((C10/IFERROR(INDEX(Config!B:B,MATCH("TVA "&A10,Config!A:A,0)),1.055))*0.42,2),"") -> #ERROR! | M10: =IFERROR(ROUND((C10/IFERROR(INDEX(Config!B:B,MATCH("TVA "&A10,Config!A:A,0)),1.055))*0.58,2),"") -> #ERROR! | N10: =IFERROR(ROUND((C10/IFERROR(INDEX(Config!B:B,MATCH("TVA "&A10,Config!A:A,0)),1.055))*0.52,2),"") -> #ERROR! | O10: =IFERROR(ROUND((C10/IFERROR(INDEX(Config!B:B,MATCH("TVA "&A10,Config!A:A,0)),1.055))*0.52,2),"") -> #ERROR! | P10: =IFERROR(ROUND((C10/IFERROR(INDEX(Config!B:B,MATCH("TVA "&A10,Config!A:A,0)),1.055))*0.55,2),"") -> #ERROR! | Q10: =IFERROR(ROUND((C10/IFERROR(INDEX(Config!B:B,MATCH("TVA "&A10,Config!A:A,0)),1.055))*0.5,2),"") -> #ERROR! | R10: =IFERROR(ROUND((C10/IFERROR(INDEX(Config!B:B,MATCH("TVA "&A10,Config!A:A,0)),1.055))*0.5,2),"") -> #ERROR! | S10: =IFERROR(ROUND((C10/IFERROR(INDEX(Config!B:B,MATCH("TVA "&A10,Config!A:A,0)),1.055))*0.62,2),"") -> #ERROR! | T10: =IFERROR(ROUND((C10/IFERROR(INDEX(Config!B:B,MATCH("TVA "&A10,Config!A:A,0)),1.055))*0.58,2),"") -> #ERROR! | U10: =IFERROR(ROUND((C10/IFERROR(INDEX(Config!B:B,MATCH("TVA "&A10,Config!A:A,0)),1.055))*0.58,2),"") -> #ERROR! | V10: =IFERROR(((C10/IFERROR(INDEX(Config!B:B,MATCH("TVA "&A10,Config!A:A,0)),1.055))-IFERROR(INDEX('Cout de Revient'!I:I,MATCH(B10,'Cout de Revient'!C:C,0)),0))/(C10/IFERROR(INDEX(Config!B:B,MATCH("TVA "&A10,Config!A:A,0)),1.055)),"") -> #ERROR! | W10: =IFERROR(C10,"") -> #ERROR! | X10: =IFERROR(ROUND(C10*0.85,2),"") -> #ERROR!
A11: Pates & Terrines | B11: RR100-850 | C11: 13.9 | D11: =IFERROR(ROUND(C11*0.95,2),"") -> #ERROR! | E11: =IFERROR(ROUND(C11*0.92,2),"") -> #ERROR! | F11: =IFERROR(ROUND(C11*0.88,2),"") -> #ERROR! | G11: =IFERROR(ROUND(C11*1,2),"") -> #ERROR! | H11: =IFERROR(ROUND(C11*0.97,2),"") -> #ERROR! | I11: =IFERROR(ROUND(C11*0.94,2),"") -> #ERROR! | J11: =IFERROR(ROUND((C11/IFERROR(INDEX(Config!B:B,MATCH("TVA "&A11,Config!A:A,0)),1.055))*0.55,2),"") -> #ERROR! | K11: =IFERROR(ROUND((C11/IFERROR(INDEX(Config!B:B,MATCH("TVA "&A11,Config!A:A,0)),1.055))*0.48,2),"") -> #ERROR! | L11: =IFERROR(ROUND((C11/IFERROR(INDEX(Config!B:B,MATCH("TVA "&A11,Config!A:A,0)),1.055))*0.42,2),"") -> #ERROR! | M11: =IFERROR(ROUND((C11/IFERROR(INDEX(Config!B:B,MATCH("TVA "&A11,Config!A:A,0)),1.055))*0.58,2),"") -> #ERROR! | N11: =IFERROR(ROUND((C11/IFERROR(INDEX(Config!B:B,MATCH("TVA "&A11,Config!A:A,0)),1.055))*0.52,2),"") -> #ERROR! | O11: =IFERROR(ROUND((C11/IFERROR(INDEX(Config!B:B,MATCH("TVA "&A11,Config!A:A,0)),1.055))*0.52,2),"") -> #ERROR! | P11: =IFERROR(ROUND((C11/IFERROR(INDEX(Config!B:B,MATCH("TVA "&A11,Config!A:A,0)),1.055))*0.55,2),"") -> #ERROR! | Q11: =IFERROR(ROUND((C11/IFERROR(INDEX(Config!B:B,MATCH("TVA "&A11,Config!A:A,0)),1.055))*0.5,2),"") -> #ERROR! | R11: =IFERROR(ROUND((C11/IFERROR(INDEX(Config!B:B,MATCH("TVA "&A11,Config!A:A,0)),1.055))*0.5,2),"") -> #ERROR! | S11: =IFERROR(ROUND((C11/IFERROR(INDEX(Config!B:B,MATCH("TVA "&A11,Config!A:A,0)),1.055))*0.62,2),"") -> #ERROR! | T11: =IFERROR(ROUND((C11/IFERROR(INDEX(Config!B:B,MATCH("TVA "&A11,Config!A:A,0)),1.055))*0.58,2),"") -> #ERROR! | U11: =IFERROR(ROUND((C11/IFERROR(INDEX(Config!B:B,MATCH("TVA "&A11,Config!A:A,0)),1.055))*0.58,2),"") -> #ERROR! | V11: =IFERROR(((C11/IFERROR(INDEX(Config!B:B,MATCH("TVA "&A11,Config!A:A,0)),1.055))-IFERROR(INDEX('Cout de Revient'!I:I,MATCH(B11,'Cout de Revient'!C:C,0)),0))/(C11/IFERROR(INDEX(Config!B:B,MATCH("TVA "&A11,Config!A:A,0)),1.055)),"") -> #ERROR! | W11: =IFERROR(C11,"") -> #ERROR! | X11: =IFERROR(ROUND(C11*0.85,2),"") -> #ERROR!
A12: Pates & Terrines | B12: RR100-1050 | C12: 17.9 | D12: =IFERROR(ROUND(C12*0.95,2),"") -> #ERROR! | E12: =IFERROR(ROUND(C12*0.92,2),"") -> #ERROR! | F12: =IFERROR(ROUND(C12*0.88,2),"") -> #ERROR! | G12: =IFERROR(ROUND(C12*1,2),"") -> #ERROR! | H12: =IFERROR(ROUND(C12*0.97,2),"") -> #ERROR! | I12: =IFERROR(ROUND(C12*0.94,2),"") -> #ERROR! | J12: =IFERROR(ROUND((C12/IFERROR(INDEX(Config!B:B,MATCH("TVA "&A12,Config!A:A,0)),1.055))*0.55,2),"") -> #ERROR! | K12: =IFERROR(ROUND((C12/IFERROR(INDEX(Config!B:B,MATCH("TVA "&A12,Config!A:A,0)),1.055))*0.48,2),"") -> #ERROR! | L12: =IFERROR(ROUND((C12/IFERROR(INDEX(Config!B:B,MATCH("TVA "&A12,Config!A:A,0)),1.055))*0.42,2),"") -> #ERROR! | M12: =IFERROR(ROUND((C12/IFERROR(INDEX(Config!B:B,MATCH("TVA "&A12,Config!A:A,0)),1.055))*0.58,2),"") -> #ERROR! | N12: =IFERROR(ROUND((C12/IFERROR(INDEX(Config!B:B,MATCH("TVA "&A12,Config!A:A,0)),1.055))*0.52,2),"") -> #ERROR! | O12: =IFERROR(ROUND((C12/IFERROR(INDEX(Config!B:B,MATCH("TVA "&A12,Config!A:A,0)),1.055))*0.52,2),"") -> #ERROR! | P12: =IFERROR(ROUND((C12/IFERROR(INDEX(Config!B:B,MATCH("TVA "&A12,Config!A:A,0)),1.055))*0.55,2),"") -> #ERROR! | Q12: =IFERROR(ROUND((C12/IFERROR(INDEX(Config!B:B,MATCH("TVA "&A12,Config!A:A,0)),1.055))*0.5,2),"") -> #ERROR! | R12: =IFERROR(ROUND((C12/IFERROR(INDEX(Config!B:B,MATCH("TVA "&A12,Config!A:A,0)),1.055))*0.5,2),"") -> #ERROR! | S12: =IFERROR(ROUND((C12/IFERROR(INDEX(Config!B:B,MATCH("TVA "&A12,Config!A:A,0)),1.055))*0.62,2),"") -> #ERROR! | T12: =IFERROR(ROUND((C12/IFERROR(INDEX(Config!B:B,MATCH("TVA "&A12,Config!A:A,0)),1.055))*0.58,2),"") -> #ERROR! | U12: =IFERROR(ROUND((C12/IFERROR(INDEX(Config!B:B,MATCH("TVA "&A12,Config!A:A,0)),1.055))*0.58,2),"") -> #ERROR! | V12: =IFERROR(((C12/IFERROR(INDEX(Config!B:B,MATCH("TVA "&A12,Config!A:A,0)),1.055))-IFERROR(INDEX('Cout de Revient'!I:I,MATCH(B12,'Cout de Revient'!C:C,0)),0))/(C12/IFERROR(INDEX(Config!B:B,MATCH("TVA "&A12,Config!A:A,0)),1.055)),"") -> #ERROR! | W12: =IFERROR(C12,"") -> #ERROR! | X12: =IFERROR(ROUND(C12*0.85,2),"") -> #ERROR!
A13: Pates & Terrines | B13: RR100-1550 | C13: 24.9 | D13: =IFERROR(ROUND(C13*0.95,2),"") -> #ERROR! | E13: =IFERROR(ROUND(C13*0.92,2),"") -> #ERROR! | F13: =IFERROR(ROUND(C13*0.88,2),"") -> #ERROR! | G13: =IFERROR(ROUND(C13*1,2),"") -> #ERROR! | H13: =IFERROR(ROUND(C13*0.97,2),"") -> #ERROR! | I13: =IFERROR(ROUND(C13*0.94,2),"") -> #ERROR! | J13: =IFERROR(ROUND((C13/IFERROR(INDEX(Config!B:B,MATCH("TVA "&A13,Config!A:A,0)),1.055))*0.55,2),"") -> #ERROR! | K13: =IFERROR(ROUND((C13/IFERROR(INDEX(Config!B:B,MATCH("TVA "&A13,Config!A:A,0)),1.055))*0.48,2),"") -> #ERROR! | L13: =IFERROR(ROUND((C13/IFERROR(INDEX(Config!B:B,MATCH("TVA "&A13,Config!A:A,0)),1.055))*0.42,2),"") -> #ERROR! | M13: =IFERROR(ROUND((C13/IFERROR(INDEX(Config!B:B,MATCH("TVA "&A13,Config!A:A,0)),1.055))*0.58,2),"") -> #ERROR! | N13: =IFERROR(ROUND((C13/IFERROR(INDEX(Config!B:B,MATCH("TVA "&A13,Config!A:A,0)),1.055))*0.52,2),"") -> #ERROR! | O13: =IFERROR(ROUND((C13/IFERROR(INDEX(Config!B:B,MATCH("TVA "&A13,Config!A:A,0)),1.055))*0.52,2),"") -> #ERROR! | P13: =IFERROR(ROUND((C13/IFERROR(INDEX(Config!B:B,MATCH("TVA "&A13,Config!A:A,0)),1.055))*0.55,2),"") -> #ERROR! | Q13: =IFERROR(ROUND((C13/IFERROR(INDEX(Config!B:B,MATCH("TVA "&A13,Config!A:A,0)),1.055))*0.5,2),"") -> #ERROR! | R13: =IFERROR(ROUND((C13/IFERROR(INDEX(Config!B:B,MATCH("TVA "&A13,Config!A:A,0)),1.055))*0.5,2),"") -> #ERROR! | S13: =IFERROR(ROUND((C13/IFERROR(INDEX(Config!B:B,MATCH("TVA "&A13,Config!A:A,0)),1.055))*0.62,2),"") -> #ERROR! | T13: =IFERROR(ROUND((C13/IFERROR(INDEX(Config!B:B,MATCH("TVA "&A13,Config!A:A,0)),1.055))*0.58,2),"") -> #ERROR! | U13: =IFERROR(ROUND((C13/IFERROR(INDEX(Config!B:B,MATCH("TVA "&A13,Config!A:A,0)),1.055))*0.58,2),"") -> #ERROR! | V13: =IFERROR(((C13/IFERROR(INDEX(Config!B:B,MATCH("TVA "&A13,Config!A:A,0)),1.055))-IFERROR(INDEX('Cout de Revient'!I:I,MATCH(B13,'Cout de Revient'!C:C,0)),0))/(C13/IFERROR(INDEX(Config!B:B,MATCH("TVA "&A13,Config!A:A,0)),1.055)),"") -> #ERROR! | W13: =IFERROR(C13,"") -> #ERROR! | X13: =IFERROR(ROUND(C13*0.85,2),"") -> #ERROR!
A14: Pates & Terrines | B14: W60-050 | C14: 2.5 | D14: =IFERROR(ROUND(C14*0.95,2),"") -> #ERROR! | E14: =IFERROR(ROUND(C14*0.92,2),"") -> #ERROR! | F14: =IFERROR(ROUND(C14*0.88,2),"") -> #ERROR! | G14: =IFERROR(ROUND(C14*1,2),"") -> #ERROR! | H14: =IFERROR(ROUND(C14*0.97,2),"") -> #ERROR! | I14: =IFERROR(ROUND(C14*0.94,2),"") -> #ERROR! | J14: =IFERROR(ROUND((C14/IFERROR(INDEX(Config!B:B,MATCH("TVA "&A14,Config!A:A,0)),1.055))*0.55,2),"") -> #ERROR! | K14: =IFERROR(ROUND((C14/IFERROR(INDEX(Config!B:B,MATCH("TVA "&A14,Config!A:A,0)),1.055))*0.48,2),"") -> #ERROR! | L14: =IFERROR(ROUND((C14/IFERROR(INDEX(Config!B:B,MATCH("TVA "&A14,Config!A:A,0)),1.055))*0.42,2),"") -> #ERROR! | M14: =IFERROR(ROUND((C14/IFERROR(INDEX(Config!B:B,MATCH("TVA "&A14,Config!A:A,0)),1.055))*0.58,2),"") -> #ERROR! | N14: =IFERROR(ROUND((C14/IFERROR(INDEX(Config!B:B,MATCH("TVA "&A14,Config!A:A,0)),1.055))*0.52,2),"") -> #ERROR! | O14: =IFERROR(ROUND((C14/IFERROR(INDEX(Config!B:B,MATCH("TVA "&A14,Config!A:A,0)),1.055))*0.52,2),"") -> #ERROR! | P14: =IFERROR(ROUND((C14/IFERROR(INDEX(Config!B:B,MATCH("TVA "&A14,Config!A:A,0)),1.055))*0.55,2),"") -> #ERROR! | Q14: =IFERROR(ROUND((C14/IFERROR(INDEX(Config!B:B,MATCH("TVA "&A14,Config!A:A,0)),1.055))*0.5,2),"") -> #ERROR! | R14: =IFERROR(ROUND((C14/IFERROR(INDEX(Config!B:B,MATCH("TVA "&A14,Config!A:A,0)),1.055))*0.5,2),"") -> #ERROR! | S14: =IFERROR(ROUND((C14/IFERROR(INDEX(Config!B:B,MATCH("TVA "&A14,Config!A:A,0)),1.055))*0.62,2),"") -> #ERROR! | T14: =IFERROR(ROUND((C14/IFERROR(INDEX(Config!B:B,MATCH("TVA "&A14,Config!A:A,0)),1.055))*0.58,2),"") -> #ERROR! | U14: =IFERROR(ROUND((C14/IFERROR(INDEX(Config!B:B,MATCH("TVA "&A14,Config!A:A,0)),1.055))*0.58,2),"") -> #ERROR! | V14: =IFERROR(((C14/IFERROR(INDEX(Config!B:B,MATCH("TVA "&A14,Config!A:A,0)),1.055))-IFERROR(INDEX('Cout de Revient'!I:I,MATCH(B14,'Cout de Revient'!C:C,0)),0))/(C14/IFERROR(INDEX(Config!B:B,MATCH("TVA "&A14,Config!A:A,0)),1.055)),"") -> #ERROR! | W14: =IFERROR(C14,"") -> #ERROR! | X14: =IFERROR(ROUND(C14*0.85,2),"") -> #ERROR!
A15: Pates & Terrines | B15: W60-080 | C15: 3.5 | D15: =IFERROR(ROUND(C15*0.95,2),"") -> #ERROR! | E15: =IFERROR(ROUND(C15*0.92,2),"") -> #ERROR! | F15: =IFERROR(ROUND(C15*0.88,2),"") -> #ERROR! | G15: =IFERROR(ROUND(C15*1,2),"") -> #ERROR! | H15: =IFERROR(ROUND(C15*0.97,2),"") -> #ERROR! | I15: =IFERROR(ROUND(C15*0.94,2),"") -> #ERROR! | J15: =IFERROR(ROUND((C15/IFERROR(INDEX(Config!B:B,MATCH("TVA "&A15,Config!A:A,0)),1.055))*0.55,2),"") -> #ERROR! | K15: =IFERROR(ROUND((C15/IFERROR(INDEX(Config!B:B,MATCH("TVA "&A15,Config!A:A,0)),1.055))*0.48,2),"") -> #ERROR! | L15: =IFERROR(ROUND((C15/IFERROR(INDEX(Config!B:B,MATCH("TVA "&A15,Config!A:A,0)),1.055))*0.42,2),"") -> #ERROR! | M15: =IFERROR(ROUND((C15/IFERROR(INDEX(Config!B:B,MATCH("TVA "&A15,Config!A:A,0)),1.055))*0.58,2),"") -> #ERROR! | N15: =IFERROR(ROUND((C15/IFERROR(INDEX(Config!B:B,MATCH("TVA "&A15,Config!A:A,0)),1.055))*0.52,2),"") -> #ERROR! | O15: =IFERROR(ROUND((C15/IFERROR(INDEX(Config!B:B,MATCH("TVA "&A15,Config!A:A,0)),1.055))*0.52,2),"") -> #ERROR! | P15: =IFERROR(ROUND((C15/IFERROR(INDEX(Config!B:B,MATCH("TVA "&A15,Config!A:A,0)),1.055))*0.55,2),"") -> #ERROR! | Q15: =IFERROR(ROUND((C15/IFERROR(INDEX(Config!B:B,MATCH("TVA "&A15,Config!A:A,0)),1.055))*0.5,2),"") -> #ERROR! | R15: =IFERROR(ROUND((C15/IFERROR(INDEX(Config!B:B,MATCH("TVA "&A15,Config!A:A,0)),1.055))*0.5,2),"") -> #ERROR! | S15: =IFERROR(ROUND((C15/IFERROR(INDEX(Config!B:B,MATCH("TVA "&A15,Config!A:A,0)),1.055))*0.62,2),"") -> #ERROR! | T15: =IFERROR(ROUND((C15/IFERROR(INDEX(Config!B:B,MATCH("TVA "&A15,Config!A:A,0)),1.055))*0.58,2),"") -> #ERROR! | U15: =IFERROR(ROUND((C15/IFERROR(INDEX(Config!B:B,MATCH("TVA "&A15,Config!A:A,0)),1.055))*0.58,2),"") -> #ERROR! | V15: =IFERROR(((C15/IFERROR(INDEX(Config!B:B,MATCH("TVA "&A15,Config!A:A,0)),1.055))-IFERROR(INDEX('Cout de Revient'!I:I,MATCH(B15,'Cout de Revient'!C:C,0)),0))/(C15/IFERROR(INDEX(Config!B:B,MATCH("TVA "&A15,Config!A:A,0)),1.055)),"") -> #ERROR! | W15: =IFERROR(C15,"") -> #ERROR! | X15: =IFERROR(ROUND(C15*0.85,2),"") -> #ERROR!
A16: Pates & Terrines | B16: W60-160 | C16: 4.9 | D16: =IFERROR(ROUND(C16*0.95,2),"") -> #ERROR! | E16: =IFERROR(ROUND(C16*0.92,2),"") -> #ERROR! | F16: =IFERROR(ROUND(C16*0.88,2),"") -> #ERROR! | G16: =IFERROR(ROUND(C16*1,2),"") -> #ERROR! | H16: =IFERROR(ROUND(C16*0.97,2),"") -> #ERROR! | I16: =IFERROR(ROUND(C16*0.94,2),"") -> #ERROR! | J16: =IFERROR(ROUND((C16/IFERROR(INDEX(Config!B:B,MATCH("TVA "&A16,Config!A:A,0)),1.055))*0.55,2),"") -> #ERROR! | K16: =IFERROR(ROUND((C16/IFERROR(INDEX(Config!B:B,MATCH("TVA "&A16,Config!A:A,0)),1.055))*0.48,2),"") -> #ERROR! | L16: =IFERROR(ROUND((C16/IFERROR(INDEX(Config!B:B,MATCH("TVA "&A16,Config!A:A,0)),1.055))*0.42,2),"") -> #ERROR! | M16: =IFERROR(ROUND((C16/IFERROR(INDEX(Config!B:B,MATCH("TVA "&A16,Config!A:A,0)),1.055))*0.58,2),"") -> #ERROR! | N16: =IFERROR(ROUND((C16/IFERROR(INDEX(Config!B:B,MATCH("TVA "&A16,Config!A:A,0)),1.055))*0.52,2),"") -> #ERROR! | O16: =IFERROR(ROUND((C16/IFERROR(INDEX(Config!B:B,MATCH("TVA "&A16,Config!A:A,0)),1.055))*0.52,2),"") -> #ERROR! | P16: =IFERROR(ROUND((C16/IFERROR(INDEX(Config!B:B,MATCH("TVA "&A16,Config!A:A,0)),1.055))*0.55,2),"") -> #ERROR! | Q16: =IFERROR(ROUND((C16/IFERROR(INDEX(Config!B:B,MATCH("TVA "&A16,Config!A:A,0)),1.055))*0.5,2),"") -> #ERROR! | R16: =IFERROR(ROUND((C16/IFERROR(INDEX(Config!B:B,MATCH("TVA "&A16,Config!A:A,0)),1.055))*0.5,2),"") -> #ERROR! | S16: =IFERROR(ROUND((C16/IFERROR(INDEX(Config!B:B,MATCH("TVA "&A16,Config!A:A,0)),1.055))*0.62,2),"") -> #ERROR! | T16: =IFERROR(ROUND((C16/IFERROR(INDEX(Config!B:B,MATCH("TVA "&A16,Config!A:A,0)),1.055))*0.58,2),"") -> #ERROR! | U16: =IFERROR(ROUND((C16/IFERROR(INDEX(Config!B:B,MATCH("TVA "&A16,Config!A:A,0)),1.055))*0.58,2),"") -> #ERROR! | V16: =IFERROR(((C16/IFERROR(INDEX(Config!B:B,MATCH("TVA "&A16,Config!A:A,0)),1.055))-IFERROR(INDEX('Cout de Revient'!I:I,MATCH(B16,'Cout de Revient'!C:C,0)),0))/(C16/IFERROR(INDEX(Config!B:B,MATCH("TVA "&A16,Config!A:A,0)),1.055)),"") -> #ERROR! | W16: =IFERROR(C16,"") -> #ERROR! | X16: =IFERROR(ROUND(C16*0.85,2),"") -> #ERROR!
A17: RILLETTES — TVA 5%
A18: Rillettes | B18: RR100-290 | C18: 5.9 | D18: =IFERROR(ROUND(C18*0.95,2),"") -> #ERROR! | E18: =IFERROR(ROUND(C18*0.92,2),"") -> #ERROR! | F18: =IFERROR(ROUND(C18*0.88,2),"") -> #ERROR! | G18: =IFERROR(ROUND(C18*1,2),"") -> #ERROR! | H18: =IFERROR(ROUND(C18*0.97,2),"") -> #ERROR! | I18: =IFERROR(ROUND(C18*0.94,2),"") -> #ERROR! | J18: =IFERROR(ROUND((C18/IFERROR(INDEX(Config!B:B,MATCH("TVA "&A18,Config!A:A,0)),1.055))*0.55,2),"") -> #ERROR! | K18: =IFERROR(ROUND((C18/IFERROR(INDEX(Config!B:B,MATCH("TVA "&A18,Config!A:A,0)),1.055))*0.48,2),"") -> #ERROR! | L18: =IFERROR(ROUND((C18/IFERROR(INDEX(Config!B:B,MATCH("TVA "&A18,Config!A:A,0)),1.055))*0.42,2),"") -> #ERROR! | M18: =IFERROR(ROUND((C18/IFERROR(INDEX(Config!B:B,MATCH("TVA "&A18,Config!A:A,0)),1.055))*0.58,2),"") -> #ERROR! | N18: =IFERROR(ROUND((C18/IFERROR(INDEX(Config!B:B,MATCH("TVA "&A18,Config!A:A,0)),1.055))*0.52,2),"") -> #ERROR! | O18: =IFERROR(ROUND((C18/IFERROR(INDEX(Config!B:B,MATCH("TVA "&A18,Config!A:A,0)),1.055))*0.52,2),"") -> #ERROR! | P18: =IFERROR(ROUND((C18/IFERROR(INDEX(Config!B:B,MATCH("TVA "&A18,Config!A:A,0)),1.055))*0.55,2),"") -> #ERROR! | Q18: =IFERROR(ROUND((C18/IFERROR(INDEX(Config!B:B,MATCH("TVA "&A18,Config!A:A,0)),1.055))*0.5,2),"") -> #ERROR! | R18: =IFERROR(ROUND((C18/IFERROR(INDEX(Config!B:B,MATCH("TVA "&A18,Config!A:A,0)),1.055))*0.5,2),"") -> #ERROR! | S18: =IFERROR(ROUND((C18/IFERROR(INDEX(Config!B:B,MATCH("TVA "&A18,Config!A:A,0)),1.055))*0.62,2),"") -> #ERROR! | T18: =IFERROR(ROUND((C18/IFERROR(INDEX(Config!B:B,MATCH("TVA "&A18,Config!A:A,0)),1.055))*0.58,2),"") -> #ERROR! | U18: =IFERROR(ROUND((C18/IFERROR(INDEX(Config!B:B,MATCH("TVA "&A18,Config!A:A,0)),1.055))*0.58,2),"") -> #ERROR! | V18: =IFERROR(((C18/IFERROR(INDEX(Config!B:B,MATCH("TVA "&A18,Config!A:A,0)),1.055))-IFERROR(INDEX('Cout de Revient'!I:I,MATCH(B18,'Cout de Revient'!C:C,0)),0))/(C18/IFERROR(INDEX(Config!B:B,MATCH("TVA "&A18,Config!A:A,0)),1.055)),"") -> #ERROR! | W18: =IFERROR(C18,"") -> #ERROR! | X18: =IFERROR(ROUND(C18*0.85,2),"") -> #ERROR!
